<?xml version="1.0" encoding="utf-8"?>
<!-- =================================================================================== -->
<!-- |    This document was autogenerated by xacro from xarm.urdf.xacro                | -->
<!-- |    EDITING THIS FILE BY HAND IS NOT RECOMMENDED                                 | -->
<!-- =================================================================================== -->
<robot name="xarm" xmlns:xacro="http://wiki.ros.org/xacro">
  <transmission name="trans">
    <type>transmission_interface/SimpleTransmission</type>
    <joint name="arm_joint1">
      <hardwareInterface>hardware_interface/PositionJointInterface</hardwareInterface>
    </joint>
    <actuator name="motor">
      <mechanicalReduction>1</mechanicalReduction>
    </actuator>
  </transmission>
  <transmission name="trans">
    <type>transmission_interface/SimpleTransmission</type>
    <joint name="arm_joint2">
      <hardwareInterface>hardware_interface/PositionJointInterface</hardwareInterface>
    </joint>
    <actuator name="motor">
      <mechanicalReduction>1</mechanicalReduction>
    </actuator>
  </transmission>
  <transmission name="trans">
    <type>transmission_interface/SimpleTransmission</type>
    <joint name="arm_joint3">
      <hardwareInterface>hardware_interface/PositionJointInterface</hardwareInterface>
    </joint>
    <actuator name="motor">
      <mechanicalReduction>1</mechanicalReduction>
    </actuator>
  </transmission>
  <transmission name="trans">
    <type>transmission_interface/SimpleTransmission</type>
    <joint name="arm_joint4">
      <hardwareInterface>hardware_interface/PositionJointInterface</hardwareInterface>
    </joint>
    <actuator name="motor">
      <mechanicalReduction>1</mechanicalReduction>
    </actuator>
  </transmission>
  <transmission name="trans">
    <type>transmission_interface/SimpleTransmission</type>
    <joint name="arm_joint5">
      <hardwareInterface>hardware_interface/PositionJointInterface</hardwareInterface>
    </joint>
    <actuator name="motor">
      <mechanicalReduction>1</mechanicalReduction>
    </actuator>
  </transmission>
  <transmission name="trans">
    <type>transmission_interface/SimpleTransmission</type>
    <joint name="gripper_joint1">
      <hardwareInterface>hardware_interface/PositionJointInterface</hardwareInterface>
    </joint>
    <actuator name="motor">
      <mechanicalReduction>1</mechanicalReduction>
    </actuator>
  </transmission>
  <transmission name="trans">
    <type>transmission_interface/SimpleTransmission</type>
    <joint name="gripper_joint2">
      <hardwareInterface>hardware_interface/PositionJointInterface</hardwareInterface>
    </joint>
    <actuator name="motor">
      <mechanicalReduction>1</mechanicalReduction>
    </actuator>
  </transmission>
  <!-- ros_control plugin -->
  <gazebo>
    <plugin filename="libgazebo_ros_control.so" name="gazebo_ros_control">
      <robotNamespace>/xarm</robotNamespace>
    </plugin>
  </gazebo>
  <gazebo reference="base_link">
    <material>Gazebo/Black</material>
  </gazebo>
  <gazebo reference="arm_link1">
    <material>Gazebo/Orange</material>
  </gazebo>
  <gazebo reference="arm_link2">
    <material>Gazebo/Orange</material>
  </gazebo>
  <gazebo reference="arm_link3">
    <material>Gazebo/Orange</material>
  </gazebo>
  <gazebo reference="arm_link4">
    <material>Gazebo/Orange</material>
  </gazebo>
  <gazebo reference="arm_link5">
    <material>Gazebo/Orange</material>
  </gazebo>
  <gazebo reference="gripper_link">
    <material>Gazebo/Red</material>
  </gazebo>
  <gazebo reference="left_gripper">
    <material>Gazebo/Red</material>
  </gazebo>
  <gazebo reference="right_gripper">
    <material>Gazebo/Red</material>
  </gazebo>
  <!-- Define the colors used in this robot -->
  <material name="Black">
    <color rgba="0 0 0 1"/>
  </material>
  <material name="White">
    <color rgba="1 1 1 1"/>
  </material>
  <material name="Blue">
    <color rgba="0.1 0.1 1 1"/>
  </material>
  <!--////////// BASE_LINK //////////-->
  <link name="base_link">
    <visual>
      <geometry>
        <box size="0.154 0.14 0.022"/>
      </geometry>
      <origin rpy="0 0 0" xyz="0 0 0.011"/>
      <material name="Black"/>
    </visual>
    <collision>
      <geometry>
        <box size="0.154 0.14 0.022"/>
      </geometry>
      <origin rpy="0 0 0" xyz="0 0 0.011"/>
    </collision>
    <inertial>
      <mass value="2*1"/>
      <inertia ixx="1" ixy="0" ixz="0" iyy="0.5" iyz="0" izz="1"/>
    </inertial>
  </link>
  <!--////////// ARM_LINK1 //////////-->
  <link name="arm_link1">
    <visual>
      <geometry>
        <cylinder length="0.05" radius="0.045"/>
      </geometry>
      <origin rpy="0 0 0" xyz="0 0 0.025"/>
      <material name="Blue"/>
    </visual>
    <collision>
      <geometry>
        <cylinder length="0.05" radius="0.045"/>
      </geometry>
      <origin rpy="0 0 0" xyz="0 0 0.025"/>
    </collision>
    <inertial>
      <mass value="0.5*1"/>
      <inertia ixx="1" ixy="0" ixz="0" iyy="0.5" iyz="0" izz="1"/>
    </inertial>
  </link>
  <joint name="arm_joint1" type="revolute">
    <origin rpy="0 0 0" xyz="0 0 0.022"/>
    <parent link="base_link"/>
    <child link="arm_link1"/>
    <axis xyz="0 0 1"/>
    <limit effort="16" lower="-2.09439510239" upper="2.09439510239" velocity="2.5"/>
    <dynamics damping="50" friction="1"/>
  </joint>
  <!--////////// ARM_LINK2 //////////-->
  <link name="arm_link2">
    <visual>
      <geometry>
        <box size="0.032 0.045 0.096"/>
      </geometry>
      <origin rpy="0 0 0" xyz="0 0 0.048"/>
      <material name="Blue"/>
    </visual>
    <collision>
      <geometry>
        <box size="0.032 0.045 0.096"/>
      </geometry>
      <origin rpy="0 0 0" xyz="0 0 0.048"/>
    </collision>
    <inertial>
      <mass value="0.15*1"/>
      <inertia ixx="1" ixy="0" ixz="0" iyy="0.5" iyz="0" izz="1"/>
    </inertial>
  </link>
  <joint name="arm_joint2" type="revolute">
    <origin rpy="0 0 0" xyz="0.003 0 0.05"/>
    <parent link="arm_link1"/>
    <child link="arm_link2"/>
    <axis xyz="0 1 0"/>
    <limit effort="16" lower="-1.57079632679" upper="1.57079632679" velocity="2"/>
    <dynamics damping="50" friction="1"/>
  </joint>
  <!--////////// ARM_LINK3 //////////-->
  <link name="arm_link3">
    <visual>
      <geometry>
        <box size="0.032 0.045 0.096"/>
      </geometry>
      <origin rpy="0 0 0" xyz="0 0 0.048"/>
      <material name="Blue"/>
    </visual>
    <collision>
      <geometry>
        <box size="0.032 0.045 0.096"/>
      </geometry>
      <origin rpy="0 0 0" xyz="0 0 0.048"/>
    </collision>
    <inertial>
      <mass value="0.15*1"/>
      <inertia ixx="1" ixy="0" ixz="0" iyy="0.5" iyz="0" izz="1"/>
    </inertial>
  </link>
  <joint name="arm_joint3" type="revolute">
    <origin rpy="0 0 0" xyz="0 0 0.096"/>
    <parent link="arm_link2"/>
    <child link="arm_link3"/>
    <axis xyz="0 1 0"/>
    <limit effort="16" lower="-2.0944" upper="2.0944" velocity="2"/>
    <dynamics damping="50" friction="1"/>
  </joint>
  <!--////////// ARM_LINK4 //////////-->
  <link name="arm_link4">
    <visual>
      <geometry>
        <box size="0.032 0.045 0.05"/>
      </geometry>
      <origin rpy="0 0 0" xyz="0 0 0.025"/>
      <material name="Blue"/>
    </visual>
    <collision>
      <geometry>
        <box size="0.032 0.045 0.05"/>
      </geometry>
      <origin rpy="0 0 0" xyz="0 0 0.025"/>
    </collision>
    <inertial>
      <mass value="0.07*1"/>
      <inertia ixx="1" ixy="0" ixz="0" iyy="0.5" iyz="0" izz="1"/>
    </inertial>
  </link>
  <joint name="arm_joint4" type="revolute">
    <origin rpy="0 0 0" xyz="0 0 0.096"/>
    <parent link="arm_link3"/>
    <child link="arm_link4"/>
    <axis xyz="0 1 0"/>
    <limit effort="16" lower="-2.0944" upper="2.0944" velocity="2"/>
    <dynamics damping="50" friction="1"/>
  </joint>
  <!--////////// ARM_LINK5 //////////-->
  <link name="arm_link5">
    <visual>
      <geometry>
        <cylinder length="0.05" radius="0.016"/>
      </geometry>
      <origin rpy="0 0 0" xyz="0 0 0.025"/>
      <material name="Blue"/>
    </visual>
    <collision>
      <geometry>
        <cylinder length="0.05" radius="0.016"/>
      </geometry>
      <origin rpy="0 0 0" xyz="0 0 0.025"/>
    </collision>
    <inertial>
      <mass value="0.071"/>
      <inertia ixx="1" ixy="0" ixz="0" iyy="0.5" iyz="0" izz="1"/>
    </inertial>
  </link>
  <joint name="arm_joint5" type="revolute">
    <origin rpy="0 0 0" xyz="0 0 0.05"/>
    <parent link="arm_link4"/>
    <child link="arm_link5"/>
    <axis xyz="0 0 1"/>
    <limit effort="16" lower="-2.09439510239" upper="2.09439510239" velocity="2.5"/>
    <dynamics damping="50" friction="1"/>
  </joint>
  <!--////////// GRIPPER_LINK //////////-->
  <link name="gripper_link">
    <visual>
      <geometry>
        <box size="0.01 0.06 0.004"/>
      </geometry>
      <origin rpy="0 0 0" xyz="0 0 0.002"/>
      <material name="White"/>
    </visual>
    <collision>
      <geometry>
        <box size="0.01 0.06 0.004"/>
      </geometry>
      <origin rpy="0 0 0" xyz="0 0 0.002"/>
    </collision>
    <inertial>
      <mass value="0.05*1"/>
      <inertia ixx="1" ixy="0" ixz="0" iyy="0.5" iyz="0" izz="1"/>
    </inertial>
  </link>
  <joint name="arm_to_gripper" type="fixed">
    <origin rpy="0 0 0" xyz="0 0 0.05"/>
    <parent link="arm_link5"/>
    <child link="gripper_link"/>
  </joint>
  <!--////////// LEFT_GRIPPER //////////-->
  <link name="left_gripper">
    <visual>
      <geometry>
        <box size="0.01 0.01 0.032"/>
      </geometry>
      <origin rpy="0 0 0" xyz="0 0 0.016"/>
      <material name="White"/>
    </visual>
    <collision>
      <geometry>
        <box size="0.01 0.01 0.032"/>
      </geometry>
      <origin rpy="0 0 0" xyz="0 0 0.016"/>
    </collision>
    <inertial>
      <mass value="0.02*1"/>
      <inertia ixx="1" ixy="0" ixz="0" iyy="0.5" iyz="0" izz="1"/>
    </inertial>
  </link>
  <joint name="gripper_joint1" type="prismatic">
    <origin rpy="0 0 0" xyz="0 -0.03 0.004"/>
    <parent link="gripper_link"/>
    <child link="left_gripper"/>
    <axis xyz="0 1 0"/>
    <limit effort="16" lower="0" upper="0.03" velocity="2"/>
    <dynamics damping="50" friction="1"/>
  </joint>
  <!--////////// RIGHT_GRIPPER //////////-->
  <link name="right_gripper">
    <visual>
      <geometry>
        <box size="0.01 0.01 0.032"/>
      </geometry>
      <origin rpy="0 0 0" xyz="0 0 0.016"/>
      <material name="White"/>
    </visual>
    <collision>
      <geometry>
        <box size="0.01 0.01 0.032"/>
      </geometry>
      <origin rpy="0 0 0" xyz="0 0 0.016"/>
    </collision>
    <inertial>
      <mass value="0.02*1"/>
      <inertia ixx="1" ixy="0" ixz="0" iyy="0.5" iyz="0" izz="1"/>
    </inertial>
  </link>
  <joint name="gripper_joint2" type="prismatic">
    <origin rpy="0 0 0" xyz="0 0.03 0.004"/>
    <parent link="gripper_link"/>
    <child link="right_gripper"/>
    <axis xyz="0 1 0"/>
    <limit effort="16" lower="-0.03" upper="0" velocity="2"/>
    <mimic joint="gripper_joint1" multiplier="-1"/>
    <dynamics damping="50" friction="1"/>
  </joint>
</robot>
